<robot name = "robot">
    <link name="Torso">
        <inertial>
            <origin xyz="0 0 1.5" rpy="0 0 0"/>
            <mass value="1" />
            <inertia ixx="100" ixy="0" ixz="0" iyy="100" iyz="0" izz="100" />
        </inertial>
        <visual>
            <origin xyz="0 0 1.5" rpy="0 0 0"/>
            <geometry>
                <box size="3 1.5 0.6" />
            </geometry>
            <material name="Cyan">
                <color rgba="0 1.0 1.0 1.0"/>
            </material>
        </visual>
        <collision>
            <origin xyz="0 0 1.5" rpy="0 0 0"/>
            <geometry>
                <box size="3 1.5 0.6" />
            </geometry>
        </collision>
    </link>
    <joint name="Torso_FrontLeftSide" type="revolute">
       <parent link="Torso"/>
       <child  link="FrontLeftSide"/>
       <origin rpy="0 0 0" xyz="-1.3 -0.75 1.3" />
       <axis xyz="0 1 0"/>
       <limit effort="0.0" lower="-3.14159" upper="3.14159" velocity="0.0"/>
    </joint>
    <link name="FrontLeftSide">
        <inertial>
            <origin xyz="0 -0.15 0" rpy="0 0 0"/>
            <mass value="1" />
            <inertia ixx="100" ixy="0" ixz="0" iyy="100" iyz="0" izz="100" />
        </inertial>
        <visual>
            <origin xyz="0 -0.15 0" rpy="0 0 0"/>
            <geometry>
                <box size="0.3 0.3 0.3" />
            </geometry>
            <material name="Cyan">
                <color rgba="0 1.0 1.0 1.0"/>
            </material>
        </visual>
        <collision>
            <origin xyz="0 -0.15 0" rpy="0 0 0"/>
            <geometry>
                <box size="0.3 0.3 0.3" />
            </geometry>
        </collision>
    </link>
    <joint name="Torso_FrontRightSide" type="revolute">
       <parent link="Torso"/>
       <child  link="FrontRightSide"/>
       <origin rpy="0 0 0" xyz="-1.3 0.75 1.3" />
       <axis xyz="0 1 0"/>
       <limit effort="0.0" lower="-3.14159" upper="3.14159" velocity="0.0"/>
    </joint>
    <link name="FrontRightSide">
        <inertial>
            <origin xyz="0 0.15 0" rpy="0 0 0"/>
            <mass value="1" />
            <inertia ixx="100" ixy="0" ixz="0" iyy="100" iyz="0" izz="100" />
        </inertial>
        <visual>
            <origin xyz="0 0.15 0" rpy="0 0 0"/>
            <geometry>
                <box size="0.3 0.3 0.3" />
            </geometry>
            <material name="Cyan">
                <color rgba="0 1.0 1.0 1.0"/>
            </material>
        </visual>
        <collision>
            <origin xyz="0 0.15 0" rpy="0 0 0"/>
            <geometry>
                <box size="0.3 0.3 0.3" />
            </geometry>
        </collision>
    </link>
    <joint name="Torso_BackLeftSide" type="revolute">
       <parent link="Torso"/>
       <child  link="BackLeftSide"/>
       <origin rpy="0 0 0" xyz="1.3 -0.75 1.3" />
       <axis xyz="0 1 0"/>
       <limit effort="0.0" lower="-3.14159" upper="3.14159" velocity="0.0"/>
    </joint>
    <link name="BackLeftSide">
        <inertial>
            <origin xyz="0 -0.15 0" rpy="0 0 0"/>
            <mass value="1" />
            <inertia ixx="100" ixy="0" ixz="0" iyy="100" iyz="0" izz="100" />
        </inertial>
        <visual>
            <origin xyz="0 -0.15 0" rpy="0 0 0"/>
            <geometry>
                <box size="0.3 0.3 0.3" />
            </geometry>
            <material name="Cyan">
                <color rgba="0 1.0 1.0 1.0"/>
            </material>
        </visual>
        <collision>
            <origin xyz="0 -0.15 0" rpy="0 0 0"/>
            <geometry>
                <box size="0.3 0.3 0.3" />
            </geometry>
        </collision>
    </link>
    <joint name="Torso_BackRightSide" type="revolute">
       <parent link="Torso"/>
       <child  link="BackRightSide"/>
       <origin rpy="0 0 0" xyz="1.3 0.75 1.3" />
       <axis xyz="0 1 0"/>
       <limit effort="0.0" lower="-3.14159" upper="3.14159" velocity="0.0"/>
    </joint>
    <link name="BackRightSide">
        <inertial>
            <origin xyz="0 0.15 0" rpy="0 0 0"/>
            <mass value="1" />
            <inertia ixx="100" ixy="0" ixz="0" iyy="100" iyz="0" izz="100" />
        </inertial>
        <visual>
            <origin xyz="0 0.15 0" rpy="0 0 0"/>
            <geometry>
                <box size="0.3 0.3 0.3" />
            </geometry>
            <material name="Cyan">
                <color rgba="0 1.0 1.0 1.0"/>
            </material>
        </visual>
        <collision>
            <origin xyz="0 0.15 0" rpy="0 0 0"/>
            <geometry>
                <box size="0.3 0.3 0.3" />
            </geometry>
        </collision>
    </link>
    <joint name="FrontLeftSide_FrontLeftUpLeg" type="revolute">
       <parent link="FrontLeftSide"/>
       <child  link="FrontLeftUpLeg"/>
       <origin rpy="0 0 0" xyz="0.15 -0.15 -0.15" />
       <axis xyz="0 1 0"/>
       <limit effort="0.0" lower="-3.14159" upper="3.14159" velocity="0.0"/>
    </joint>
    <link name="FrontLeftUpLeg">
        <inertial>
            <origin xyz="0.15 0 -0.25" rpy="0 0 0"/>
            <mass value="1" />
            <inertia ixx="100" ixy="0" ixz="0" iyy="100" iyz="0" izz="100" />
        </inertial>
        <visual>
            <origin xyz="0.15 0 -0.25" rpy="0 0 0"/>
            <geometry>
                <box size="0.3 0.3 0.5" />
            </geometry>
            <material name="Cyan">
                <color rgba="0 1.0 1.0 1.0"/>
            </material>
        </visual>
        <collision>
            <origin xyz="0.15 0 -0.25" rpy="0 0 0"/>
            <geometry>
                <box size="0.3 0.3 0.5" />
            </geometry>
        </collision>
    </link>
    <joint name="FrontRightSide_FrontRightUpLeg" type="revolute">
       <parent link="FrontRightSide"/>
       <child  link="FrontRightUpLeg"/>
       <origin rpy="0 0 0" xyz="0.15 0.15 -0.15" />
       <axis xyz="0 1 0"/>
       <limit effort="0.0" lower="-3.14159" upper="3.14159" velocity="0.0"/>
    </joint>
    <link name="FrontRightUpLeg">
        <inertial>
            <origin xyz="0.15 0 -0.25" rpy="0 0 0"/>
            <mass value="1" />
            <inertia ixx="100" ixy="0" ixz="0" iyy="100" iyz="0" izz="100" />
        </inertial>
        <visual>
            <origin xyz="0.15 0 -0.25" rpy="0 0 0"/>
            <geometry>
                <box size="0.3 0.3 0.5" />
            </geometry>
            <material name="Cyan">
                <color rgba="0 1.0 1.0 1.0"/>
            </material>
        </visual>
        <collision>
            <origin xyz="0.15 0 -0.25" rpy="0 0 0"/>
            <geometry>
                <box size="0.3 0.3 0.5" />
            </geometry>
        </collision>
    </link>
    <joint name="BackLeftSide_BackLeftUpLeg" type="revolute">
       <parent link="BackLeftSide"/>
       <child  link="BackLeftUpLeg"/>
       <origin rpy="0 0 0" xyz="0.15 -0.15 -0.15" />
       <axis xyz="0 1 0"/>
       <limit effort="0.0" lower="-3.14159" upper="3.14159" velocity="0.0"/>
    </joint>
    <link name="BackLeftUpLeg">
        <inertial>
            <origin xyz="0.15 0 -0.25" rpy="0 0 0"/>
            <mass value="1" />
            <inertia ixx="100" ixy="0" ixz="0" iyy="100" iyz="0" izz="100" />
        </inertial>
        <visual>
            <origin xyz="0.15 0 -0.25" rpy="0 0 0"/>
            <geometry>
                <box size="0.3 0.3 0.5" />
            </geometry>
            <material name="Cyan">
                <color rgba="0 1.0 1.0 1.0"/>
            </material>
        </visual>
        <collision>
            <origin xyz="0.15 0 -0.25" rpy="0 0 0"/>
            <geometry>
                <box size="0.3 0.3 0.5" />
            </geometry>
        </collision>
    </link>
    <joint name="BackRightSide_BackRightUpLeg" type="revolute">
       <parent link="BackRightSide"/>
       <child  link="BackRightUpLeg"/>
       <origin rpy="0 0 0" xyz="0.15 0.15 -0.15" />
       <axis xyz="0 1 0"/>
       <limit effort="0.0" lower="-3.14159" upper="3.14159" velocity="0.0"/>
    </joint>
    <link name="BackRightUpLeg">
        <inertial>
            <origin xyz="0.15 0 -0.25" rpy="0 0 0"/>
            <mass value="1" />
            <inertia ixx="100" ixy="0" ixz="0" iyy="100" iyz="0" izz="100" />
        </inertial>
        <visual>
            <origin xyz="0.15 0 -0.25" rpy="0 0 0"/>
            <geometry>
                <box size="0.3 0.3 0.5" />
            </geometry>
            <material name="Cyan">
                <color rgba="0 1.0 1.0 1.0"/>
            </material>
        </visual>
        <collision>
            <origin xyz="0.15 0 -0.25" rpy="0 0 0"/>
            <geometry>
                <box size="0.3 0.3 0.5" />
            </geometry>
        </collision>
    </link>
    <joint name="FrontLeftUpLeg_FrontLeftDownLeg" type="revolute">
       <parent link="FrontLeftUpLeg"/>
       <child  link="FrontLeftDownLeg"/>
       <origin rpy="0 0 0" xyz="0.3 0 -0.5" />
       <axis xyz="0 1 0"/>
       <limit effort="0.0" lower="-3.14159" upper="3.14159" velocity="0.0"/>
    </joint>
    <link name="FrontLeftDownLeg">
        <inertial>
            <origin xyz="0.1 0 -0.3" rpy="0 0 0"/>
            <mass value="1" />
            <inertia ixx="100" ixy="0" ixz="0" iyy="100" iyz="0" izz="100" />
        </inertial>
        <visual>
            <origin xyz="0.1 0 -0.3" rpy="0 0 0"/>
            <geometry>
                <box size="0.2 0.2 0.6" />
            </geometry>
            <material name="Cyan">
                <color rgba="0 1.0 1.0 1.0"/>
            </material>
        </visual>
        <collision>
            <origin xyz="0.1 0 -0.3" rpy="0 0 0"/>
            <geometry>
                <box size="0.2 0.2 0.6" />
            </geometry>
        </collision>
    </link>
    <joint name="FrontRightUpLeg_FrontRightDownLeg" type="revolute">
       <parent link="FrontRightUpLeg"/>
       <child  link="FrontRightDownLeg"/>
       <origin rpy="0 0 0" xyz="0.3 0 -0.5" />
       <axis xyz="0 1 0"/>
       <limit effort="0.0" lower="-3.14159" upper="3.14159" velocity="0.0"/>
    </joint>
    <link name="FrontRightDownLeg">
        <inertial>
            <origin xyz="0.1 0 -0.3" rpy="0 0 0"/>
            <mass value="1" />
            <inertia ixx="100" ixy="0" ixz="0" iyy="100" iyz="0" izz="100" />
        </inertial>
        <visual>
            <origin xyz="0.1 0 -0.3" rpy="0 0 0"/>
            <geometry>
                <box size="0.2 0.2 0.6" />
            </geometry>
            <material name="Cyan">
                <color rgba="0 1.0 1.0 1.0"/>
            </material>
        </visual>
        <collision>
            <origin xyz="0.1 0 -0.3" rpy="0 0 0"/>
            <geometry>
                <box size="0.2 0.2 0.6" />
            </geometry>
        </collision>
    </link>
    <joint name="BackLeftUpLeg_BackLeftDownLeg" type="revolute">
       <parent link="BackLeftUpLeg"/>
       <child  link="BackLeftDownLeg"/>
       <origin rpy="0 0 0" xyz="0.3 0 -0.5" />
       <axis xyz="0 1 0"/>
       <limit effort="0.0" lower="-3.14159" upper="3.14159" velocity="0.0"/>
    </joint>
    <link name="BackLeftDownLeg">
        <inertial>
            <origin xyz="0.1 0 -0.3" rpy="0 0 0"/>
            <mass value="1" />
            <inertia ixx="100" ixy="0" ixz="0" iyy="100" iyz="0" izz="100" />
        </inertial>
        <visual>
            <origin xyz="0.1 0 -0.3" rpy="0 0 0"/>
            <geometry>
                <box size="0.2 0.2 0.6" />
            </geometry>
            <material name="Cyan">
                <color rgba="0 1.0 1.0 1.0"/>
            </material>
        </visual>
        <collision>
            <origin xyz="0.1 0 -0.3" rpy="0 0 0"/>
            <geometry>
                <box size="0.2 0.2 0.6" />
            </geometry>
        </collision>
    </link>
    <joint name="BackRightUpLeg_BackRightDownLeg" type="revolute">
       <parent link="BackRightUpLeg"/>
       <child  link="BackRightDownLeg"/>
       <origin rpy="0 0 0" xyz="0.3 0 -0.5" />
       <axis xyz="0 1 0"/>
       <limit effort="0.0" lower="-3.14159" upper="3.14159" velocity="0.0"/>
    </joint>
    <link name="BackRightDownLeg">
        <inertial>
            <origin xyz="0.1 0 -0.3" rpy="0 0 0"/>
            <mass value="1" />
            <inertia ixx="100" ixy="0" ixz="0" iyy="100" iyz="0" izz="100" />
        </inertial>
        <visual>
            <origin xyz="0.1 0 -0.3" rpy="0 0 0"/>
            <geometry>
                <box size="0.2 0.2 0.6" />
            </geometry>
            <material name="Cyan">
                <color rgba="0 1.0 1.0 1.0"/>
            </material>
        </visual>
        <collision>
            <origin xyz="0.1 0 -0.3" rpy="0 0 0"/>
            <geometry>
                <box size="0.2 0.2 0.6" />
            </geometry>
        </collision>
    </link>
    <joint name="FrontLeftDownLeg_FrontLeftFoot" type="revolute">
       <parent link="FrontLeftDownLeg"/>
       <child  link="FrontLeftFoot"/>
       <origin rpy="0 0 0" xyz="0.1 0 -0.6" />
       <axis xyz="1 0 0"/>
       <limit effort="0.0" lower="-3.14159" upper="3.14159" velocity="0.0"/>
    </joint>
    <link name="FrontLeftFoot">
        <inertial>
            <origin xyz="-0.2 0 -0.05" rpy="0 0 0"/>
            <mass value="1" />
            <inertia ixx="100" ixy="0" ixz="0" iyy="100" iyz="0" izz="100" />
        </inertial>
        <visual>
            <origin xyz="-0.2 0 -0.05" rpy="0 0 0"/>
            <geometry>
                <box size="0.4 0.2 0.1" />
            </geometry>
            <material name="Cyan">
                <color rgba="0 1.0 1.0 1.0"/>
            </material>
        </visual>
        <collision>
            <origin xyz="-0.2 0 -0.05" rpy="0 0 0"/>
            <geometry>
                <box size="0.4 0.2 0.1" />
            </geometry>
        </collision>
    </link>
    <joint name="FrontRightDownLeg_FrontRightFoot" type="revolute">
       <parent link="FrontRightDownLeg"/>
       <child  link="FrontRightFoot"/>
       <origin rpy="0 0 0" xyz="0.1 0 -0.6" />
       <axis xyz="1 0 0"/>
       <limit effort="0.0" lower="-3.14159" upper="3.14159" velocity="0.0"/>
    </joint>
    <link name="FrontRightFoot">
        <inertial>
            <origin xyz="-0.2 0 -0.05" rpy="0 0 0"/>
            <mass value="1" />
            <inertia ixx="100" ixy="0" ixz="0" iyy="100" iyz="0" izz="100" />
        </inertial>
        <visual>
            <origin xyz="-0.2 0 -0.05" rpy="0 0 0"/>
            <geometry>
                <box size="0.4 0.2 0.1" />
            </geometry>
            <material name="Cyan">
                <color rgba="0 1.0 1.0 1.0"/>
            </material>
        </visual>
        <collision>
            <origin xyz="-0.2 0 -0.05" rpy="0 0 0"/>
            <geometry>
                <box size="0.4 0.2 0.1" />
            </geometry>
        </collision>
    </link>
    <joint name="BackLeftDownLeg_BackLeftFoot" type="revolute">
       <parent link="BackLeftDownLeg"/>
       <child  link="BackLeftFoot"/>
       <origin rpy="0 0 0" xyz="0.1 0 -0.6" />
       <axis xyz="1 0 0"/>
       <limit effort="0.0" lower="-3.14159" upper="3.14159" velocity="0.0"/>
    </joint>
    <link name="BackLeftFoot">
        <inertial>
            <origin xyz="-0.2 0 -0.05" rpy="0 0 0"/>
            <mass value="1" />
            <inertia ixx="100" ixy="0" ixz="0" iyy="100" iyz="0" izz="100" />
        </inertial>
        <visual>
            <origin xyz="-0.2 0 -0.05" rpy="0 0 0"/>
            <geometry>
                <box size="0.4 0.2 0.1" />
            </geometry>
            <material name="Cyan">
                <color rgba="0 1.0 1.0 1.0"/>
            </material>
        </visual>
        <collision>
            <origin xyz="-0.2 0 -0.05" rpy="0 0 0"/>
            <geometry>
                <box size="0.4 0.2 0.1" />
            </geometry>
        </collision>
    </link>
    <joint name="BackRightDownLeg_BackRightFoot" type="revolute">
       <parent link="BackRightDownLeg"/>
       <child  link="BackRightFoot"/>
       <origin rpy="0 0 0" xyz="0.1 0 -0.6" />
       <axis xyz="1 0 0"/>
       <limit effort="0.0" lower="-3.14159" upper="3.14159" velocity="0.0"/>
    </joint>
    <link name="BackRightFoot">
        <inertial>
            <origin xyz="-0.2 0 -0.05" rpy="0 0 0"/>
            <mass value="1" />
            <inertia ixx="100" ixy="0" ixz="0" iyy="100" iyz="0" izz="100" />
        </inertial>
        <visual>
            <origin xyz="-0.2 0 -0.05" rpy="0 0 0"/>
            <geometry>
                <box size="0.4 0.2 0.1" />
            </geometry>
            <material name="Cyan">
                <color rgba="0 1.0 1.0 1.0"/>
            </material>
        </visual>
        <collision>
            <origin xyz="-0.2 0 -0.05" rpy="0 0 0"/>
            <geometry>
                <box size="0.4 0.2 0.1" />
            </geometry>
        </collision>
    </link>
</robot>